<?xml version="1.0"?>
<sdf version="1.9">
  <model name="tether">
    <link name="link_00">
      <gravity>true</gravity>
      <pose>-0.1 0 0 0 0 0</pose>
      <inertial>
        <mass>0.009</mass>
        <pose>0.1 0 0 0 0 0</pose>
        <inertia>
          <ixx>0.01</ixx>
          <ixy>0</ixy>
          <ixz>0</ixz>
          <iyy>0.01</iyy>
          <iyz>0</iyz>
          <izz>0.01</izz>
        </inertia>
      </inertial>
      <visual name="visual">
        <pose>0.1 0 0 0 1.570790 0</pose>
        <geometry>
          <cylinder>
            <length>0.2</length>
            <radius>0.001</radius>
          </cylinder>
        </geometry>
        <material>
          <ambient>1 1 1</ambient>
          <diffuse>1 1 1</diffuse>
          <specular>0.01 0.01 0.01 1.0</specular>
        </material>
      </visual>
      <visual name="sphere">
        <geometry>
          <sphere>
            <radius>0.009</radius>
          </sphere>
        </geometry>
        <material>
          <ambient>1 0 0</ambient>
          <diffuse>1 0 0</diffuse>
          <specular>0.01 0.01 0.01 1.0</specular>
        </material>
      </visual>
    </link>
    <link name="link_01">
      <gravity>true</gravity>
      <pose>0.1 0 0 0 0 0</pose>
      <inertial>
        <mass>0.009</mass>
        <pose>0.1 0 0 0 0 0</pose>
        <inertia>
          <ixx>0.01</ixx>
          <ixy>0</ixy>
          <ixz>0</ixz>
          <iyy>0.01</iyy>
          <iyz>0</iyz>
          <izz>0.01</izz>
        </inertia>
      </inertial>
      <collision name="collision">
        <pose>0.1 0 0 0 1.570790 0</pose>
        <geometry>
          <cylinder>
            <length>0.2</length>
            <radius>0.001</radius>
          </cylinder>
        </geometry>
        <surface>
          <contact>
            <ode>
              <min_depth>0.00005</min_depth>
            </ode>
          </contact>
          <friction>
            <ode>
              <mu>1.0</mu>
              <mu2>1.0</mu2>
            </ode>
          </friction>
        </surface>
      </collision>
      <visual name="visual">
        <pose>0.1 0 0 0 1.570790 0</pose>
        <geometry>
          <cylinder>
            <length>0.2</length>
            <radius>0.001</radius>
          </cylinder>
        </geometry>
        <material>
          <ambient>1 1 1</ambient>
          <diffuse>1 1 1</diffuse>
          <specular>0.01 0.01 0.01 1.0</specular>
        </material>
      </visual>
      <visual name="sphere">
        <geometry>
          <sphere>
            <radius>0.009</radius>
          </sphere>
        </geometry>
        <material>
          <ambient>1 0 0</ambient>
          <diffuse>1 0 0</diffuse>
          <specular>0.01 0.01 0.01 1.0</specular>
        </material>
      </visual>
    </link>
    <link name="link_02">
      <gravity>true</gravity>
      <pose>0.3 0 0 0 0 0</pose>
      <inertial>
        <mass>0.009</mass>
        <pose>0.1 0 0 0 0 0</pose>
        <inertia>
          <ixx>0.01</ixx>
          <ixy>0</ixy>
          <ixz>0</ixz>
          <iyy>0.01</iyy>
          <iyz>0</iyz>
          <izz>0.01</izz>
        </inertia>
      </inertial>
      <collision name="collision">
        <pose>0.1 0 0 0 1.570790 0</pose>
        <geometry>
          <cylinder>
            <length>0.2</length>
            <radius>0.001</radius>
          </cylinder>
        </geometry>
        <surface>
          <contact>
            <ode>
              <min_depth>0.00005</min_depth>
            </ode>
          </contact>
          <friction>
            <ode>
              <mu>1.0</mu>
              <mu2>1.0</mu2>
            </ode>
          </friction>
        </surface>
      </collision>
      <visual name="visual">
        <pose>0.1 0 0 0 1.570790 0</pose>
        <geometry>
          <cylinder>
            <length>0.2</length>
            <radius>0.001</radius>
          </cylinder>
        </geometry>
        <material>
          <ambient>1 1 1</ambient>
          <diffuse>1 1 1</diffuse>
          <specular>0.01 0.01 0.01 1.0</specular>
        </material>
      </visual>
      <visual name="sphere">
        <geometry>
          <sphere>
            <radius>0.009</radius>
          </sphere>
        </geometry>
        <material>
          <ambient>1 0 0</ambient>
          <diffuse>1 0 0</diffuse>
          <specular>0.01 0.01 0.01 1.0</specular>
        </material>
      </visual>
    </link>
    <link name="link_03">
      <gravity>true</gravity>
      <pose>0.5 0 0 0 0 0</pose>
      <inertial>
        <mass>0.009</mass>
        <pose>0.1 0 0 0 0 0</pose>
        <inertia>
          <ixx>0.01</ixx>
          <ixy>0</ixy>
          <ixz>0</ixz>
          <iyy>0.01</iyy>
          <iyz>0</iyz>
          <izz>0.01</izz>
        </inertia>
      </inertial>
      <collision name="collision">
        <pose>0.1 0 0 0 1.570790 0</pose>
        <geometry>
          <cylinder>
            <length>0.2</length>
            <radius>0.001</radius>
          </cylinder>
        </geometry>
        <surface>
          <contact>
            <ode>
              <min_depth>0.00005</min_depth>
            </ode>
          </contact>
          <friction>
            <ode>
              <mu>1.0</mu>
              <mu2>1.0</mu2>
            </ode>
          </friction>
        </surface>
      </collision>
      <visual name="visual">
        <pose>0.1 0 0 0 1.570790 0</pose>
        <geometry>
          <cylinder>
            <length>0.2</length>
            <radius>0.001</radius>
          </cylinder>
        </geometry>
        <material>
          <ambient>1 1 1</ambient>
          <diffuse>1 1 1</diffuse>
          <specular>0.01 0.01 0.01 1.0</specular>
        </material>
      </visual>
      <visual name="sphere">
        <geometry>
          <sphere>
            <radius>0.009</radius>
          </sphere>
        </geometry>
        <material>
          <ambient>1 0 0</ambient>
          <diffuse>1 0 0</diffuse>
          <specular>0.01 0.01 0.01 1.0</specular>
        </material>
      </visual>
    </link>
    <link name="link_04">
      <gravity>true</gravity>
      <pose>0.7 0 0 0 0 0</pose>
      <inertial>
        <mass>0.009</mass>
        <pose>0.1 0 0 0 0 0</pose>
        <inertia>
          <ixx>0.01</ixx>
          <ixy>0</ixy>
          <ixz>0</ixz>
          <iyy>0.01</iyy>
          <iyz>0</iyz>
          <izz>0.01</izz>
        </inertia>
      </inertial>
      <collision name="collision">
        <pose>0.1 0 0 0 1.570790 0</pose>
        <geometry>
          <cylinder>
            <length>0.2</length>
            <radius>0.001</radius>
          </cylinder>
        </geometry>
        <surface>
          <contact>
            <ode>
              <min_depth>0.00005</min_depth>
            </ode>
          </contact>
          <friction>
            <ode>
              <mu>1.0</mu>
              <mu2>1.0</mu2>
            </ode>
          </friction>
        </surface>
      </collision>
      <visual name="visual">
        <pose>0.1 0 0 0 1.570790 0</pose>
        <geometry>
          <cylinder>
            <length>0.2</length>
            <radius>0.001</radius>
          </cylinder>
        </geometry>
        <material>
          <ambient>1 1 1</ambient>
          <diffuse>1 1 1</diffuse>
          <specular>0.01 0.01 0.01 1.0</specular>
        </material>
      </visual>
      <visual name="sphere">
        <geometry>
          <sphere>
            <radius>0.009</radius>
          </sphere>
        </geometry>
        <material>
          <ambient>1 0 0</ambient>
          <diffuse>1 0 0</diffuse>
          <specular>0.01 0.01 0.01 1.0</specular>
        </material>
      </visual>
    </link>
    <link name="link_05">
      <gravity>true</gravity>
      <pose>0.9 0 0 0 0 0</pose>
      <inertial>
        <mass>0.009</mass>
        <pose>0.1 0 0 0 0 0</pose>
        <inertia>
          <ixx>0.01</ixx>
          <ixy>0</ixy>
          <ixz>0</ixz>
          <iyy>0.01</iyy>
          <iyz>0</iyz>
          <izz>0.01</izz>
        </inertia>
      </inertial>
      <collision name="collision">
        <pose>0.1 0 0 0 1.570790 0</pose>
        <geometry>
          <cylinder>
            <length>0.2</length>
            <radius>0.001</radius>
          </cylinder>
        </geometry>
        <surface>
          <contact>
            <ode>
              <min_depth>0.00005</min_depth>
            </ode>
          </contact>
          <friction>
            <ode>
              <mu>1.0</mu>
              <mu2>1.0</mu2>
            </ode>
          </friction>
        </surface>
      </collision>
      <visual name="visual">
        <pose>0.1 0 0 0 1.570790 0</pose>
        <geometry>
          <cylinder>
            <length>0.2</length>
            <radius>0.001</radius>
          </cylinder>
        </geometry>
        <material>
          <ambient>1 1 1</ambient>
          <diffuse>1 1 1</diffuse>
          <specular>0.01 0.01 0.01 1.0</specular>
        </material>
      </visual>
      <visual name="sphere">
        <geometry>
          <sphere>
            <radius>0.009</radius>
          </sphere>
        </geometry>
        <material>
          <ambient>1 0 0</ambient>
          <diffuse>1 0 0</diffuse>
          <specular>0.01 0.01 0.01 1.0</specular>
        </material>
      </visual>
    </link>
    <link name="link_06">
      <gravity>true</gravity>
      <pose>1.1 0 0 0 0 -.785</pose>
      <inertial>
        <mass>0.009</mass>
        <pose>0.0875 0 0 0 0 0</pose>
        <inertia>
          <ixx>0.01</ixx>
          <ixy>0</ixy>
          <ixz>0</ixz>
          <iyy>0.01</iyy>
          <iyz>0</iyz>
          <izz>0.01</izz>
        </inertia>
      </inertial>
      <collision name="collision">
        <pose>0.0875 0 0 0 1.570790 0</pose>
        <geometry>
          <cylinder>
            <length>0.175</length>
            <radius>0.001</radius>
          </cylinder>
        </geometry>
        <surface>
          <contact>
            <ode>
              <min_depth>0.00005</min_depth>
            </ode>
          </contact>
          <friction>
            <ode>
              <mu>1.0</mu>
              <mu2>1.0</mu2>
            </ode>
          </friction>
        </surface>
      </collision>
      <visual name="visual">
        <pose>0.0875 0 0 0 1.570790 0</pose>
        <geometry>
          <cylinder>
            <length>0.175</length>
            <radius>0.001</radius>
          </cylinder>
        </geometry>
        <material>
          <ambient>1 1 1</ambient>
          <diffuse>1 1 1</diffuse>
          <specular>0.01 0.01 0.01 1.0</specular>
        </material>
      </visual>
      <visual name="sphere">
        <geometry>
          <sphere>
            <radius>0.009</radius>
          </sphere>
        </geometry>
        <material>
          <ambient>1 0 0</ambient>
          <diffuse>1 0 0</diffuse>
          <specular>0.01 0.01 0.01 1.0</specular>
        </material>
      </visual>
    </link>
    <link name="link_07">
      <gravity>true</gravity>
      <pose>1.227 -.127 0 0 0 -2.3415</pose>
      <inertial>
        <mass>0.009</mass>
        <pose>0.0875 0 0 0 0 0</pose>
        <inertia>
          <ixx>0.01</ixx>
          <ixy>0</ixy>
          <ixz>0</ixz>
          <iyy>0.01</iyy>
          <iyz>0</iyz>
          <izz>0.01</izz>
        </inertia>
      </inertial>
      <collision name="collision">
        <pose>0.0875 0 0 0 1.570790 0</pose>
        <geometry>
          <cylinder>
            <length>0.175</length>
            <radius>0.001</radius>
          </cylinder>
        </geometry>
        <surface>
          <contact>
            <ode>
              <min_depth>0.00005</min_depth>
            </ode>
          </contact>
          <friction>
            <ode>
              <mu>1.0</mu>
              <mu2>1.0</mu2>
            </ode>
          </friction>
        </surface>
      </collision>
      <visual name="visual">
        <pose>0.0875 0 0 0 1.570790 0</pose>
        <geometry>
          <cylinder>
            <length>0.175</length>
            <radius>0.001</radius>
          </cylinder>
        </geometry>
        <material>
          <ambient>1 1 1</ambient>
          <diffuse>1 1 1</diffuse>
          <specular>0.01 0.01 0.01 1.0</specular>
        </material>
      </visual>
      <visual name="sphere">
        <geometry>
          <sphere>
            <radius>0.009</radius>
          </sphere>
        </geometry>
        <material>
          <ambient>1 0 0</ambient>
          <diffuse>1 0 0</diffuse>
          <specular>0.01 0.01 0.01 1.0</specular>
        </material>
      </visual>
    </link>
    <link name="link_08">
      <gravity>true</gravity>
      <pose>1.1 -.254 0 0 0 -3.1415</pose>
      <inertial>
        <mass>0.009</mass>
        <pose>0.1 0 0 0 0 0</pose>
        <inertia>
          <ixx>0.01</ixx>
          <ixy>0</ixy>
          <ixz>0</ixz>
          <iyy>0.01</iyy>
          <iyz>0</iyz>
          <izz>0.01</izz>
        </inertia>
      </inertial>
      <collision name="collision">
        <pose>0.1 0 0 0 1.570790 0</pose>
        <geometry>
          <cylinder>
            <length>0.2</length>
            <radius>0.001</radius>
          </cylinder>
        </geometry>
        <surface>
          <contact>
            <ode>
              <min_depth>0.00005</min_depth>
            </ode>
          </contact>
          <friction>
            <ode>
              <mu>1.0</mu>
              <mu2>1.0</mu2>
            </ode>
          </friction>
        </surface>
      </collision>
      <visual name="visual">
        <pose>0.1 0 0 0 1.570790 0</pose>
        <geometry>
          <cylinder>
            <length>0.2</length>
            <radius>0.001</radius>
          </cylinder>
        </geometry>
        <material>
          <ambient>1 1 1</ambient>
          <diffuse>1 1 1</diffuse>
          <specular>0.01 0.01 0.01 1.0</specular>
        </material>
      </visual>
      <visual name="sphere">
        <geometry>
          <sphere>
            <radius>0.009</radius>
          </sphere>
        </geometry>
        <material>
          <ambient>1 0 0</ambient>
          <diffuse>1 0 0</diffuse>
          <specular>0.01 0.01 0.01 1.0</specular>
        </material>
      </visual>
    </link>
    <link name="link_09">
      <gravity>true</gravity>
      <pose>0.9 -.254 0 0 0 -3.1415</pose>
      <inertial>
        <mass>0.009</mass>
        <pose>0.1 0 0 0 0 0</pose>
        <inertia>
          <ixx>0.01</ixx>
          <ixy>0</ixy>
          <ixz>0</ixz>
          <iyy>0.01</iyy>
          <iyz>0</iyz>
          <izz>0.01</izz>
        </inertia>
      </inertial>
      <collision name="collision">
        <pose>0.1 0 0 0 1.570790 0</pose>
        <geometry>
          <cylinder>
            <length>0.2</length>
            <radius>0.001</radius>
          </cylinder>
        </geometry>
        <surface>
          <contact>
            <ode>
              <min_depth>0.00005</min_depth>
            </ode>
          </contact>
          <friction>
            <ode>
              <mu>1.0</mu>
              <mu2>1.0</mu2>
            </ode>
          </friction>
        </surface>
      </collision>
      <visual name="visual">
        <pose>0.1 0 0 0 1.570790 0</pose>
        <geometry>
          <cylinder>
            <length>0.2</length>
            <radius>0.001</radius>
          </cylinder>
        </geometry>
        <material>
          <ambient>1 1 1</ambient>
          <diffuse>1 1 1</diffuse>
          <specular>0.01 0.01 0.01 1.0</specular>
        </material>
      </visual>
      <visual name="sphere">
        <geometry>
          <sphere>
            <radius>0.009</radius>
          </sphere>
        </geometry>
        <material>
          <ambient>1 0 0</ambient>
          <diffuse>1 0 0</diffuse>
          <specular>0.01 0.01 0.01 1.0</specular>
        </material>
      </visual>
    </link>
    <link name="link_10">
      <gravity>true</gravity>
      <pose>0.7 -.254 0 0 0 -3.1415</pose>
      <inertial>
        <mass>0.009</mass>
        <pose>0.1 0 0 0 0 0</pose>
        <inertia>
          <ixx>0.01</ixx>
          <ixy>0</ixy>
          <ixz>0</ixz>
          <iyy>0.01</iyy>
          <iyz>0</iyz>
          <izz>0.01</izz>
        </inertia>
      </inertial>
      <collision name="collision">
        <pose>0.1 0 0 0 1.570790 0</pose>
        <geometry>
          <cylinder>
            <length>0.2</length>
            <radius>0.001</radius>
          </cylinder>
        </geometry>
        <surface>
          <contact>
            <ode>
              <min_depth>0.00005</min_depth>
            </ode>
          </contact>
          <friction>
            <ode>
              <mu>1.0</mu>
              <mu2>1.0</mu2>
            </ode>
          </friction>
        </surface>
      </collision>
      <visual name="visual">
        <pose>0.1 0 0 0 1.570790 0</pose>
        <geometry>
          <cylinder>
            <length>0.2</length>
            <radius>0.001</radius>
          </cylinder>
        </geometry>
        <material>
          <ambient>1 1 1</ambient>
          <diffuse>1 1 1</diffuse>
          <specular>0.01 0.01 0.01 1.0</specular>
        </material>
      </visual>
      <visual name="sphere">
        <geometry>
          <sphere>
            <radius>0.009</radius>
          </sphere>
        </geometry>
        <material>
          <ambient>1 0 0</ambient>
          <diffuse>1 0 0</diffuse>
          <specular>0.01 0.01 0.01 1.0</specular>
        </material>
      </visual>
    </link>
    <link name="link_11">
      <gravity>true</gravity>
      <pose>0.5 -.254 0 0 0 -3.1415</pose>
      <inertial>
        <mass>0.009</mass>
        <pose>0.1 0 0 0 0 0</pose>
        <inertia>
          <ixx>0.01</ixx>
          <ixy>0</ixy>
          <ixz>0</ixz>
          <iyy>0.01</iyy>
          <iyz>0</iyz>
          <izz>0.01</izz>
        </inertia>
      </inertial>
      <collision name="collision">
        <pose>0.1 0 0 0 1.570790 0</pose>
        <geometry>
          <cylinder>
            <length>0.2</length>
            <radius>0.001</radius>
          </cylinder>
        </geometry>
        <surface>
          <contact>
            <ode>
              <min_depth>0.00005</min_depth>
            </ode>
          </contact>
          <friction>
            <ode>
              <mu>1.0</mu>
              <mu2>1.0</mu2>
            </ode>
          </friction>
        </surface>
      </collision>
      <visual name="visual">
        <pose>0.1 0 0 0 1.570790 0</pose>
        <geometry>
          <cylinder>
            <length>0.2</length>
            <radius>0.001</radius>
          </cylinder>
        </geometry>
        <material>
          <ambient>1 1 1</ambient>
          <diffuse>1 1 1</diffuse>
          <specular>0.01 0.01 0.01 1.0</specular>
        </material>
      </visual>
      <visual name="sphere">
        <geometry>
          <sphere>
            <radius>0.009</radius>
          </sphere>
        </geometry>
        <material>
          <ambient>1 0 0</ambient>
          <diffuse>1 0 0</diffuse>
          <specular>0.01 0.01 0.01 1.0</specular>
        </material>
      </visual>
    </link>
    <link name="link_12">
      <gravity>true</gravity>
      <pose>0.3 -.254 0 0 0 -3.1415</pose>
      <inertial>
        <mass>0.009</mass>
        <pose>0.1 0 0 0 0 0</pose>
        <inertia>
          <ixx>0.01</ixx>
          <ixy>0</ixy>
          <ixz>0</ixz>
          <iyy>0.01</iyy>
          <iyz>0</iyz>
          <izz>0.01</izz>
        </inertia>
      </inertial>
      <collision name="collision">
        <pose>0.1 0 0 0 1.570790 0</pose>
        <geometry>
          <cylinder>
            <length>0.2</length>
            <radius>0.001</radius>
          </cylinder>
        </geometry>
        <surface>
          <contact>
            <ode>
              <min_depth>0.00005</min_depth>
            </ode>
          </contact>
          <friction>
            <ode>
              <mu>1.0</mu>
              <mu2>1.0</mu2>
            </ode>
          </friction>
        </surface>
      </collision>
      <visual name="visual">
        <pose>0.1 0 0 0 1.570790 0</pose>
        <geometry>
          <cylinder>
            <length>0.2</length>
            <radius>0.001</radius>
          </cylinder>
        </geometry>
        <material>
          <ambient>1 1 1</ambient>
          <diffuse>1 1 1</diffuse>
          <specular>0.01 0.01 0.01 1.0</specular>
        </material>
      </visual>
      <visual name="sphere">
        <geometry>
          <sphere>
            <radius>0.009</radius>
          </sphere>
        </geometry>
        <material>
          <ambient>1 0 0</ambient>
          <diffuse>1 0 0</diffuse>
          <specular>0.01 0.01 0.01 1.0</specular>
        </material>
      </visual>
    </link>
    <link name="link_13">
      <gravity>true</gravity>
      <pose>0.1 -.254 0 0 0 -2.356</pose>
      <inertial>
        <mass>0.009</mass>
        <pose>0.0875 0 0 0 0 0</pose>
        <inertia>
          <ixx>0.01</ixx>
          <ixy>0</ixy>
          <ixz>0</ixz>
          <iyy>0.01</iyy>
          <iyz>0</iyz>
          <izz>0.01</izz>
        </inertia>
      </inertial>
      <collision name="collision">
        <pose>0.0875 0 0 0 1.570790 0</pose>
        <geometry>
          <cylinder>
            <length>0.175</length>
            <radius>0.001</radius>
          </cylinder>
        </geometry>
        <surface>
          <contact>
            <ode>
              <min_depth>0.00005</min_depth>
            </ode>
          </contact>
          <friction>
            <ode>
              <mu>1.0</mu>
              <mu2>1.0</mu2>
            </ode>
          </friction>
        </surface>
      </collision>
      <visual name="visual">
        <pose>0.0875 0 0 0 1.570790 0</pose>
        <geometry>
          <cylinder>
            <length>0.175</length>
            <radius>0.001</radius>
          </cylinder>
        </geometry>
        <material>
          <ambient>1 1 1</ambient>
          <diffuse>1 1 1</diffuse>
          <specular>0.01 0.01 0.01 1.0</specular>
        </material>
      </visual>
      <visual name="sphere">
        <geometry>
          <sphere>
            <radius>0.009</radius>
          </sphere>
        </geometry>
        <material>
          <ambient>1 0 0</ambient>
          <diffuse>1 0 0</diffuse>
          <specular>0.01 0.01 0.01 1.0</specular>
        </material>
      </visual>
    </link>
    <link name="link_14">
      <gravity>true</gravity>
      <pose>-0.027 -.381 0 0 0 -.785</pose>
      <inertial>
        <mass>0.009</mass>
        <pose>0.0875 0 0 0 0 0</pose>
        <inertia>
          <ixx>0.01</ixx>
          <ixy>0</ixy>
          <ixz>0</ixz>
          <iyy>0.01</iyy>
          <iyz>0</iyz>
          <izz>0.01</izz>
        </inertia>
      </inertial>
      <collision name="collision">
        <pose>0.0875 0 0 0 1.570790 0</pose>
        <geometry>
          <cylinder>
            <length>0.175</length>
            <radius>0.001</radius>
          </cylinder>
        </geometry>
        <surface>
          <contact>
            <ode>
              <min_depth>0.00005</min_depth>
            </ode>
          </contact>
          <friction>
            <ode>
              <mu>1.0</mu>
              <mu2>1.0</mu2>
            </ode>
          </friction>
        </surface>
      </collision>
      <visual name="visual">
        <pose>0.0875 0 0 0 1.570790 0</pose>
        <geometry>
          <cylinder>
            <length>0.175</length>
            <radius>0.001</radius>
          </cylinder>
        </geometry>
        <material>
          <ambient>1 1 1</ambient>
          <diffuse>1 1 1</diffuse>
          <specular>0.01 0.01 0.01 1.0</specular>
        </material>
      </visual>
      <visual name="sphere">
        <geometry>
          <sphere>
            <radius>0.009</radius>
          </sphere>
        </geometry>
        <material>
          <ambient>1 0 0</ambient>
          <diffuse>1 0 0</diffuse>
          <specular>0.01 0.01 0.01 1.0</specular>
        </material>
      </visual>
    </link>
    <link name="link_15">
      <gravity>true</gravity>
      <pose>0.1 -.508 0 0 0 0</pose>
      <inertial>
        <mass>0.009</mass>
        <pose>0.1 0 0 0 0 0</pose>
        <inertia>
          <ixx>0.01</ixx>
          <ixy>0</ixy>
          <ixz>0</ixz>
          <iyy>0.01</iyy>
          <iyz>0</iyz>
          <izz>0.01</izz>
        </inertia>
      </inertial>
      <collision name="collision">
        <pose>0.1 0 0 0 1.570790 0</pose>
        <geometry>
          <cylinder>
            <length>0.2</length>
            <radius>0.001</radius>
          </cylinder>
        </geometry>
        <surface>
          <contact>
            <ode>
              <min_depth>0.00005</min_depth>
            </ode>
          </contact>
          <friction>
            <ode>
              <mu>1.0</mu>
              <mu2>1.0</mu2>
            </ode>
          </friction>
        </surface>
      </collision>
      <visual name="visual">
        <pose>0.1 0 0 0 1.570790 0</pose>
        <geometry>
          <cylinder>
            <length>0.2</length>
            <radius>0.001</radius>
          </cylinder>
        </geometry>
        <material>
          <ambient>1 1 1</ambient>
          <diffuse>1 1 1</diffuse>
          <specular>0.01 0.01 0.01 1.0</specular>
        </material>
      </visual>
      <visual name="sphere">
        <geometry>
          <sphere>
            <radius>0.009</radius>
          </sphere>
        </geometry>
        <material>
          <ambient>1 0 0</ambient>
          <diffuse>1 0 0</diffuse>
          <specular>0.01 0.01 0.01 1.0</specular>
        </material>
      </visual>
    </link>
    <link name="link_16">
      <gravity>true</gravity>
      <pose>0.3 -.508 0 0 0 0</pose>
      <inertial>
        <mass>0.009</mass>
        <pose>0.1 0 0 0 0 0</pose>
        <inertia>
          <ixx>0.01</ixx>
          <ixy>0</ixy>
          <ixz>0</ixz>
          <iyy>0.01</iyy>
          <iyz>0</iyz>
          <izz>0.01</izz>
        </inertia>
      </inertial>
      <collision name="collision">
        <pose>0.1 0 0 0 1.570790 0</pose>
        <geometry>
          <cylinder>
            <length>0.2</length>
            <radius>0.001</radius>
          </cylinder>
        </geometry>
        <surface>
          <contact>
            <ode>
              <min_depth>0.00005</min_depth>
            </ode>
          </contact>
          <friction>
            <ode>
              <mu>1.0</mu>
              <mu2>1.0</mu2>
            </ode>
          </friction>
        </surface>
      </collision>
      <visual name="visual">
        <pose>0.1 0 0 0 1.570790 0</pose>
        <geometry>
          <cylinder>
            <length>0.2</length>
            <radius>0.001</radius>
          </cylinder>
        </geometry>
        <material>
          <ambient>1 1 1</ambient>
          <diffuse>1 1 1</diffuse>
          <specular>0.01 0.01 0.01 1.0</specular>
        </material>
      </visual>
      <visual name="sphere">
        <geometry>
          <sphere>
            <radius>0.009</radius>
          </sphere>
        </geometry>
        <material>
          <ambient>1 0 0</ambient>
          <diffuse>1 0 0</diffuse>
          <specular>0.01 0.01 0.01 1.0</specular>
        </material>
      </visual>
    </link>
    <link name="link_17">
      <gravity>true</gravity>
      <pose>0.5 -.508 0 0 0 0</pose>
      <inertial>
        <mass>0.009</mass>
        <pose>0.1 0 0 0 0 0</pose>
        <inertia>
          <ixx>0.01</ixx>
          <ixy>0</ixy>
          <ixz>0</ixz>
          <iyy>0.01</iyy>
          <iyz>0</iyz>
          <izz>0.01</izz>
        </inertia>
      </inertial>
      <collision name="collision">
        <pose>0.1 0 0 0 1.570790 0</pose>
        <geometry>
          <cylinder>
            <length>0.2</length>
            <radius>0.001</radius>
          </cylinder>
        </geometry>
        <surface>
          <contact>
            <ode>
              <min_depth>0.00005</min_depth>
            </ode>
          </contact>
          <friction>
            <ode>
              <mu>1.0</mu>
              <mu2>1.0</mu2>
            </ode>
          </friction>
        </surface>
      </collision>
      <visual name="visual">
        <pose>0.1 0 0 0 1.570790 0</pose>
        <geometry>
          <cylinder>
            <length>0.2</length>
            <radius>0.001</radius>
          </cylinder>
        </geometry>
        <material>
          <ambient>1 1 1</ambient>
          <diffuse>1 1 1</diffuse>
          <specular>0.01 0.01 0.01 1.0</specular>
        </material>
      </visual>
      <visual name="sphere">
        <geometry>
          <sphere>
            <radius>0.009</radius>
          </sphere>
        </geometry>
        <material>
          <ambient>1 0 0</ambient>
          <diffuse>1 0 0</diffuse>
          <specular>0.01 0.01 0.01 1.0</specular>
        </material>
      </visual>
    </link>
    <link name="link_18">
      <gravity>true</gravity>
      <pose>0.7 -.508 0 0 0 0</pose>
      <inertial>
        <mass>0.009</mass>
        <pose>0.1 0 0 0 0 0</pose>
        <inertia>
          <ixx>0.01</ixx>
          <ixy>0</ixy>
          <ixz>0</ixz>
          <iyy>0.01</iyy>
          <iyz>0</iyz>
          <izz>0.01</izz>
        </inertia>
      </inertial>
      <collision name="collision">
        <pose>0.1 0 0 0 1.570790 0</pose>
        <geometry>
          <cylinder>
            <length>0.2</length>
            <radius>0.001</radius>
          </cylinder>
        </geometry>
        <surface>
          <contact>
            <ode>
              <min_depth>0.00005</min_depth>
            </ode>
          </contact>
          <friction>
            <ode>
              <mu>1.0</mu>
              <mu2>1.0</mu2>
            </ode>
          </friction>
        </surface>
      </collision>
      <visual name="visual">
        <pose>0.1 0 0 0 1.570790 0</pose>
        <geometry>
          <cylinder>
            <length>0.2</length>
            <radius>0.001</radius>
          </cylinder>
        </geometry>
        <material>
          <ambient>1 1 1</ambient>
          <diffuse>1 1 1</diffuse>
          <specular>0.01 0.01 0.01 1.0</specular>
        </material>
      </visual>
      <visual name="sphere">
        <geometry>
          <sphere>
            <radius>0.009</radius>
          </sphere>
        </geometry>
        <material>
          <ambient>1 0 0</ambient>
          <diffuse>1 0 0</diffuse>
          <specular>0.01 0.01 0.01 1.0</specular>
        </material>
      </visual>
    </link>
    <link name="link_19">
      <gravity>true</gravity>
      <pose>0.9 -.508 0 0 0 0</pose>
      <inertial>
        <mass>0.009</mass>
        <pose>0.1 0 0 0 0 0</pose>
        <inertia>
          <ixx>0.01</ixx>
          <ixy>0</ixy>
          <ixz>0</ixz>
          <iyy>0.01</iyy>
          <iyz>0</iyz>
          <izz>0.01</izz>
        </inertia>
      </inertial>
      <collision name="collision">
        <pose>0.1 0 0 0 1.570790 0</pose>
        <geometry>
          <cylinder>
            <length>0.2</length>
            <radius>0.001</radius>
          </cylinder>
        </geometry>
        <surface>
          <contact>
            <ode>
              <min_depth>0.00005</min_depth>
            </ode>
          </contact>
          <friction>
            <ode>
              <mu>1.0</mu>
              <mu2>1.0</mu2>
            </ode>
          </friction>
        </surface>
      </collision>
      <visual name="sphere">
        <geometry>
          <sphere>
            <radius>0.009</radius>
          </sphere>
        </geometry>
        <material>
          <ambient>1 0 0</ambient>
          <diffuse>1 0 0</diffuse>
          <specular>0.01 0.01 0.01 1.0</specular>
        </material>
      </visual>
    </link>
    <joint name="joint_01" type="universal">
      <child>link_01</child>
      <parent>link_00</parent>
      <axis>
        <xyz>0 1 0</xyz>
        <limit>
          <lower>-1.57</lower>
          <upper>1.57</upper>
        </limit>
        <dynamics>
          <damping>0.1</damping>
          <friction>0.0</friction>
          <spring_stiffness>0.05</spring_stiffness>
          <spring_reference>0.0</spring_reference>
        </dynamics>
      </axis>
      <axis2>
        <xyz>0 0 1</xyz>
        <limit>
          <lower>-1.57</lower>
          <upper>1.57</upper>
        </limit>
        <dynamics>
          <damping>0.1</damping>
          <friction>0.0</friction>
          <spring_stiffness>0.05</spring_stiffness>
          <spring_reference>0.0</spring_reference>
        </dynamics>
      </axis2>
      <physics>
        <ode>
          <cfm_damping>1</cfm_damping>
        </ode>
      </physics>
    </joint>
    <joint name="joint_02" type="universal">
      <child>link_02</child>
      <parent>link_01</parent>
      <axis>
        <xyz>0 1 0</xyz>
        <limit>
          <lower>-1.57</lower>
          <upper>1.57</upper>
        </limit>
        <dynamics>
          <damping>0.1</damping>
          <friction>0.0</friction>
          <spring_stiffness>0.05</spring_stiffness>
          <spring_reference>0.0</spring_reference>
        </dynamics>
      </axis>
      <axis2>
        <xyz>0 0 1</xyz>
        <limit>
          <lower>-1.57</lower>
          <upper>1.57</upper>
        </limit>
        <dynamics>
          <damping>0.1</damping>
          <friction>0.0</friction>
          <spring_stiffness>0.05</spring_stiffness>
          <spring_reference>0.0</spring_reference>
        </dynamics>
      </axis2>
      <physics>
        <ode>
          <cfm_damping>1</cfm_damping>
        </ode>
      </physics>
    </joint>
    <joint name="joint_03" type="universal">
      <child>link_03</child>
      <parent>link_02</parent>
      <axis>
        <xyz>0 1 0</xyz>
        <limit>
          <lower>-1.57</lower>
          <upper>1.57</upper>
        </limit>
        <dynamics>
          <damping>0.1</damping>
          <friction>0.0</friction>
          <spring_stiffness>0.05</spring_stiffness>
          <spring_reference>0.0</spring_reference>
        </dynamics>
      </axis>
      <axis2>
        <xyz>0 0 1</xyz>
        <limit>
          <lower>-1.57</lower>
          <upper>1.57</upper>
        </limit>
        <dynamics>
          <damping>0.1</damping>
          <friction>0.0</friction>
          <spring_stiffness>0.05</spring_stiffness>
          <spring_reference>0.0</spring_reference>
        </dynamics>
      </axis2>
      <physics>
        <ode>
          <cfm_damping>1</cfm_damping>
        </ode>
      </physics>
    </joint>
    <joint name="joint_04" type="universal">
      <child>link_04</child>
      <parent>link_03</parent>
      <axis>
        <xyz>0 1 0</xyz>
        <limit>
          <lower>-1.57</lower>
          <upper>1.57</upper>
        </limit>
        <dynamics>
          <damping>0.1</damping>
          <friction>0.0</friction>
          <spring_stiffness>0.05</spring_stiffness>
          <spring_reference>0.0</spring_reference>
        </dynamics>
      </axis>
      <axis2>
        <xyz>0 0 1</xyz>
        <limit>
          <lower>-1.57</lower>
          <upper>1.57</upper>
        </limit>
        <dynamics>
          <damping>0.1</damping>
          <friction>0.0</friction>
          <spring_stiffness>0.05</spring_stiffness>
          <spring_reference>0.0</spring_reference>
        </dynamics>
      </axis2>
      <physics>
        <ode>
          <cfm_damping>1</cfm_damping>
        </ode>
      </physics>
    </joint>
    <joint name="joint_05" type="universal">
      <child>link_05</child>
      <parent>link_04</parent>
      <axis>
        <xyz>0 1 0</xyz>
        <limit>
          <lower>-1.57</lower>
          <upper>1.57</upper>
        </limit>
        <dynamics>
          <damping>0.1</damping>
          <friction>0.0</friction>
          <spring_stiffness>0.05</spring_stiffness>
          <spring_reference>0.0</spring_reference>
        </dynamics>
      </axis>
      <axis2>
        <xyz>0 0 1</xyz>
        <limit>
          <lower>-1.57</lower>
          <upper>1.57</upper>
        </limit>
        <dynamics>
          <damping>0.1</damping>
          <friction>0.0</friction>
          <spring_stiffness>0.05</spring_stiffness>
          <spring_reference>0.0</spring_reference>
        </dynamics>
      </axis2>
      <physics>
        <ode>
          <cfm_damping>1</cfm_damping>
        </ode>
      </physics>
    </joint>
    <joint name="joint_06" type="universal">
      <child>link_06</child>
      <parent>link_05</parent>
      <axis>
        <xyz>0 0 1</xyz>
        <limit>
          <lower>-0.72</lower>
          <upper>2.35</upper>
        </limit>
        <dynamics>
          <damping>0.1</damping>
          <friction>0.0</friction>
          <spring_stiffness>0.05</spring_stiffness>
          <spring_reference>0.0</spring_reference>
        </dynamics>
      </axis>
      <axis2>
        <xyz>1 1 0</xyz>
        <limit>
          <lower>-1.57</lower>
          <upper>1.57</upper>
        </limit>
        <dynamics>
          <damping>0.1</damping>
          <friction>0.0</friction>
          <spring_stiffness>0.05</spring_stiffness>
          <spring_reference>0.0</spring_reference>
        </dynamics>
      </axis2>
      <physics>
        <ode>
          <cfm_damping>1</cfm_damping>
        </ode>
      </physics>
    </joint>
    <joint name="joint_07" type="universal">
      <child>link_07</child>
      <parent>link_06</parent>
      <axis>
        <xyz>0 0 1</xyz>
        <limit>
          <lower>-0.0</lower>
          <upper>3.00</upper>
        </limit>
        <dynamics>
          <damping>0.1</damping>
          <friction>0.0</friction>
          <spring_stiffness>0.05</spring_stiffness>
          <spring_reference>0.0</spring_reference>
        </dynamics>
      </axis>
      <axis2>
        <xyz>-1 1 0</xyz>
        <limit>
          <lower>-1.57</lower>
          <upper>1.57</upper>
        </limit>
        <dynamics>
          <damping>0.1</damping>
          <friction>0.0</friction>
          <spring_stiffness>0.05</spring_stiffness>
          <spring_reference>0.0</spring_reference>
        </dynamics>
      </axis2>
      <physics>
        <ode>
          <cfm_damping>1</cfm_damping>
        </ode>
      </physics>
    </joint>
    <joint name="joint_08" type="universal">
      <child>link_08</child>
      <parent>link_07</parent>
      <axis>
        <xyz>0 1 0</xyz>
        <limit>
          <lower>-1.57</lower>
          <upper>1.57</upper>
        </limit>
        <dynamics>
          <damping>0.1</damping>
          <friction>0.0</friction>
          <spring_stiffness>0.05</spring_stiffness>
          <spring_reference>0.0</spring_reference>
        </dynamics>
      </axis>
      <axis2>
        <xyz>0 0 1</xyz>
        <limit>
          <lower>-0.72</lower>
          <upper>2.35</upper>
        </limit>
        <dynamics>
          <damping>0.1</damping>
          <friction>0.0</friction>
          <spring_stiffness>0.05</spring_stiffness>
          <spring_reference>0.0</spring_reference>
        </dynamics>
      </axis2>
      <physics>
        <ode>
          <cfm_damping>1</cfm_damping>
        </ode>
      </physics>
    </joint>
    <joint name="joint_09" type="universal">
      <child>link_09</child>
      <parent>link_08</parent>
      <axis>
        <xyz>0 1 0</xyz>
        <limit>
          <lower>-1.57</lower>
          <upper>1.57</upper>
        </limit>
        <dynamics>
          <damping>0.1</damping>
          <friction>0.0</friction>
          <spring_stiffness>0.05</spring_stiffness>
          <spring_reference>0.0</spring_reference>
        </dynamics>
      </axis>
      <axis2>
        <xyz>0 0 1</xyz>
        <limit>
          <lower>-1.57</lower>
          <upper>1.57</upper>
        </limit>
        <dynamics>
          <damping>0.1</damping>
          <friction>0.0</friction>
          <spring_stiffness>0.05</spring_stiffness>
          <spring_reference>0.0</spring_reference>
        </dynamics>
      </axis2>
      <physics>
        <ode>
          <cfm_damping>1</cfm_damping>
        </ode>
      </physics>
    </joint>
    <joint name="joint_10" type="universal">
      <child>link_10</child>
      <parent>link_09</parent>
      <axis>
        <xyz>0 1 0</xyz>
        <limit>
          <lower>-1.57</lower>
          <upper>1.57</upper>
        </limit>
        <dynamics>
          <damping>0.1</damping>
          <friction>0.0</friction>
          <spring_stiffness>0.05</spring_stiffness>
          <spring_reference>0.0</spring_reference>
        </dynamics>
      </axis>
      <axis2>
        <xyz>0 0 1</xyz>
        <limit>
          <lower>-1.57</lower>
          <upper>1.57</upper>
        </limit>
        <dynamics>
          <damping>0.1</damping>
          <friction>0.0</friction>
          <spring_stiffness>0.05</spring_stiffness>
          <spring_reference>0.0</spring_reference>
        </dynamics>
      </axis2>
      <physics>
        <ode>
          <cfm_damping>1</cfm_damping>
        </ode>
      </physics>
    </joint>
    <joint name="joint_11" type="universal">
      <child>link_11</child>
      <parent>link_10</parent>
      <axis>
        <xyz>0 1 0</xyz>
        <limit>
          <lower>-1.57</lower>
          <upper>1.57</upper>
        </limit>
        <dynamics>
          <damping>0.1</damping>
          <friction>0.0</friction>
          <spring_stiffness>0.05</spring_stiffness>
          <spring_reference>0.0</spring_reference>
        </dynamics>
      </axis>
      <axis2>
        <xyz>0 0 1</xyz>
        <limit>
          <lower>-1.57</lower>
          <upper>1.57</upper>
        </limit>
        <dynamics>
          <damping>0.1</damping>
          <friction>0.0</friction>
          <spring_stiffness>0.05</spring_stiffness>
          <spring_reference>0.0</spring_reference>
        </dynamics>
      </axis2>
      <physics>
        <ode>
          <cfm_damping>1</cfm_damping>
        </ode>
      </physics>
    </joint>
    <joint name="joint_12" type="universal">
      <child>link_12</child>
      <parent>link_11</parent>
      <axis>
        <xyz>0 1 0</xyz>
        <limit>
          <lower>-1.57</lower>
          <upper>1.57</upper>
        </limit>
        <dynamics>
          <damping>0.1</damping>
          <friction>0.0</friction>
          <spring_stiffness>0.05</spring_stiffness>
          <spring_reference>0.0</spring_reference>
        </dynamics>
      </axis>
      <axis2>
        <xyz>0 0 1</xyz>
        <limit>
          <lower>-1.57</lower>
          <upper>1.57</upper>
        </limit>
        <dynamics>
          <damping>0.1</damping>
          <friction>0.0</friction>
          <spring_stiffness>0.05</spring_stiffness>
          <spring_reference>0.0</spring_reference>
        </dynamics>
      </axis2>
      <physics>
        <ode>
          <cfm_damping>1</cfm_damping>
        </ode>
      </physics>
    </joint>
    <joint name="joint_13" type="universal">
      <child>link_13</child>
      <parent>link_12</parent>
      <axis>
        <xyz>0 0 1</xyz>
        <limit>
          <lower>-2.35</lower>
          <upper>0.72</upper>
        </limit>
        <dynamics>
          <damping>0.1</damping>
          <friction>0.0</friction>
          <spring_stiffness>0.05</spring_stiffness>
          <spring_reference>0.0</spring_reference>
        </dynamics>
      </axis>
      <axis2>
        <xyz>-1 1 0</xyz>
        <limit>
          <lower>-1.57</lower>
          <upper>1.57</upper>
        </limit>
        <dynamics>
          <damping>0.1</damping>
          <friction>0.0</friction>
          <spring_stiffness>0.05</spring_stiffness>
          <spring_reference>0.0</spring_reference>
        </dynamics>
      </axis2>
      <physics>
        <ode>
          <cfm_damping>1</cfm_damping>
        </ode>
      </physics>
    </joint>
    <joint name="joint_14" type="universal">
      <child>link_14</child>
      <parent>link_13</parent>
      <axis>
        <xyz>0 0 1</xyz>
        <limit>
          <lower>-3.00</lower>
          <upper>0.0</upper>
        </limit>
        <dynamics>
          <damping>0.1</damping>
          <friction>0.0</friction>
          <spring_stiffness>0.05</spring_stiffness>
          <spring_reference>0.0</spring_reference>
        </dynamics>
      </axis>
      <axis2>
        <xyz>1 1 0</xyz>
        <limit>
          <lower>-1.57</lower>
          <upper>1.57</upper>
        </limit>
        <dynamics>
          <damping>0.1</damping>
          <friction>0.0</friction>
          <spring_stiffness>0.05</spring_stiffness>
          <spring_reference>0.0</spring_reference>
        </dynamics>
      </axis2>
      <physics>
        <ode>
          <cfm_damping>1</cfm_damping>
        </ode>
      </physics>
    </joint>
    <joint name="joint_15" type="universal">
      <child>link_15</child>
      <parent>link_14</parent>
      <axis>
        <xyz>0 0 1</xyz>
        <limit>
          <lower>-2.35</lower>
          <upper>0.72</upper>
        </limit>
        <dynamics>
          <damping>0.1</damping>
          <friction>0.0</friction>
          <spring_stiffness>0.05</spring_stiffness>
          <spring_reference>0.0</spring_reference>
        </dynamics>
      </axis>
      <axis2>
        <xyz>0 1 0</xyz>
        <limit>
          <lower>-1.57</lower>
          <upper>1.57</upper>
        </limit>
        <dynamics>
          <damping>0.1</damping>
          <friction>0.0</friction>
          <spring_stiffness>0.05</spring_stiffness>
          <spring_reference>0.0</spring_reference>
        </dynamics>
      </axis2>
      <physics>
        <ode>
          <cfm_damping>1</cfm_damping>
        </ode>
      </physics>
    </joint>
    <joint name="joint_16" type="universal">
      <child>link_16</child>
      <parent>link_15</parent>
      <axis>
        <xyz>0 1 0</xyz>
        <limit>
          <lower>-1.57</lower>
          <upper>1.57</upper>
        </limit>
        <dynamics>
          <damping>0.1</damping>
          <friction>0.0</friction>
          <spring_stiffness>0.05</spring_stiffness>
          <spring_reference>0.0</spring_reference>
        </dynamics>
      </axis>
      <axis2>
        <xyz>0 0 1</xyz>
        <limit>
          <lower>-1.57</lower>
          <upper>1.57</upper>
        </limit>
        <dynamics>
          <damping>0.1</damping>
          <friction>0.0</friction>
          <spring_stiffness>0.05</spring_stiffness>
          <spring_reference>0.0</spring_reference>
        </dynamics>
      </axis2>
      <physics>
        <ode>
          <cfm_damping>1</cfm_damping>
        </ode>
      </physics>
    </joint>
    <joint name="joint_17" type="universal">
      <child>link_17</child>
      <parent>link_16</parent>
      <axis>
        <xyz>0 1 0</xyz>
        <limit>
          <lower>-1.57</lower>
          <upper>1.57</upper>
        </limit>
        <dynamics>
          <damping>0.1</damping>
          <friction>0.0</friction>
          <spring_stiffness>0.05</spring_stiffness>
          <spring_reference>0.0</spring_reference>
        </dynamics>
      </axis>
      <axis2>
        <xyz>0 0 1</xyz>
        <limit>
          <lower>-1.57</lower>
          <upper>1.57</upper>
        </limit>
        <dynamics>
          <damping>0.1</damping>
          <friction>0.0</friction>
          <spring_stiffness>0.05</spring_stiffness>
          <spring_reference>0.0</spring_reference>
        </dynamics>
      </axis2>
      <physics>
        <ode>
          <cfm_damping>1</cfm_damping>
        </ode>
      </physics>
    </joint>
    <joint name="joint_18" type="universal">
      <child>link_18</child>
      <parent>link_17</parent>
      <axis>
        <xyz>0 1 0</xyz>
        <limit>
          <lower>-1.57</lower>
          <upper>1.57</upper>
        </limit>
        <dynamics>
          <damping>0.1</damping>
          <friction>0.0</friction>
          <spring_stiffness>0.05</spring_stiffness>
          <spring_reference>0.0</spring_reference>
        </dynamics>
      </axis>
      <axis2>
        <xyz>0 0 1</xyz>
        <limit>
          <lower>-1.57</lower>
          <upper>1.57</upper>
        </limit>
        <dynamics>
          <damping>0.1</damping>
          <friction>0.0</friction>
          <spring_stiffness>0.05</spring_stiffness>
          <spring_reference>0.0</spring_reference>
        </dynamics>
      </axis2>
      <physics>
        <ode>
          <cfm_damping>1</cfm_damping>
        </ode>
      </physics>
    </joint>
    <joint name="joint_19" type="universal">
      <child>link_19</child>
      <parent>link_18</parent>
      <axis>
        <xyz>0 1 0</xyz>
        <limit>
          <lower>-1.57</lower>
          <upper>1.57</upper>
        </limit>
        <dynamics>
          <damping>0.1</damping>
          <friction>0.0</friction>
          <spring_stiffness>0.05</spring_stiffness>
          <spring_reference>0.0</spring_reference>
        </dynamics>
      </axis>
      <axis2>
        <xyz>0 0 1</xyz>
        <limit>
          <lower>-1.57</lower>
          <upper>1.57</upper>
        </limit>
        <dynamics>
          <damping>0.1</damping>
          <friction>0.0</friction>
          <spring_stiffness>0.05</spring_stiffness>
          <spring_reference>0.0</spring_reference>
        </dynamics>
      </axis2>
      <physics>
        <ode>
          <cfm_damping>1</cfm_damping>
        </ode>
      </physics>
    </joint>
    <!-- <joint name="fixed_to_world" type="fixed">
      <child>link_19</child>
      <parent>world</parent>
    </joint> -->

    <!-- 0.002m of diameter x 0.2 element length -->
    <!-- <plugin name="link00_drag" filename="libLiftDragPlugin.so">
      <robotNamespace></robotNamespace>
      <a0>0</a0>
      <cla>0</cla>
      <cda>1.2535816618911175</cda>
      <alpha_stall>0</alpha_stall>
      <cda_stall>1.4326647564469914</cda_stall>
      <cp>0 0 0</cp>
      <area>0.0004</area>
      <air_density>1.2041</air_density>
      <forward>0 1 0</forward>
      <upward>0 0 1</upward>
      <link_name>link_00</link_name>
    </plugin>
    <plugin name="link01_drag" filename="libLiftDragPlugin.so">
      <robotNamespace></robotNamespace>
      <a0>0</a0>
      <cla>0</cla>
      <cda>1.2535816618911175</cda>
      <alpha_stall>0</alpha_stall>
      <cda_stall>1.4326647564469914</cda_stall>
      <cp>0 0 0</cp>
      <area>0.0004</area>
      <air_density>1.2041</air_density>
      <forward>0 1 0</forward>
      <upward>0 0 1</upward>
      <link_name>link_01</link_name>
    </plugin>
    <plugin name="link02_drag" filename="libLiftDragPlugin.so">
      <robotNamespace></robotNamespace>
      <a0>0</a0>
      <cla>0</cla>
      <cda>1.2535816618911175</cda>
      <alpha_stall>0</alpha_stall>
      <cda_stall>1.4326647564469914</cda_stall>
      <cp>0 0 0</cp>
      <area>0.0004</area>
      <air_density>1.2041</air_density>
      <forward>0 1 0</forward>
      <upward>0 0 1</upward>
      <link_name>link_02</link_name>
    </plugin>
    <plugin name="link03_drag" filename="libLiftDragPlugin.so">
      <robotNamespace></robotNamespace>
      <a0>0</a0>
      <cla>0</cla>
      <cda>1.2535816618911175</cda>
      <alpha_stall>0</alpha_stall>
      <cda_stall>1.4326647564469914</cda_stall>
      <cp>0 0 0</cp>
      <area>0.0004</area>
      <air_density>1.2041</air_density>
      <forward>0 1 0</forward>
      <upward>0 0 1</upward>
      <link_name>link_03</link_name>
    </plugin>
    <plugin name="link04_drag" filename="libLiftDragPlugin.so">
      <robotNamespace></robotNamespace>
      <a0>0</a0>
      <cla>0</cla>
      <cda>1.2535816618911175</cda>
      <alpha_stall>0</alpha_stall>
      <cda_stall>1.4326647564469914</cda_stall>
      <cp>0 0 0</cp>
      <area>0.0004</area>
      <air_density>1.2041</air_density>
      <forward>0 1 0</forward>
      <upward>0 0 1</upward>
      <link_name>link_04</link_name>
    </plugin>
    <plugin name="link05_drag" filename="libLiftDragPlugin.so">
      <robotNamespace></robotNamespace>
      <a0>0</a0>
      <cla>0</cla>
      <cda>1.2535816618911175</cda>
      <alpha_stall>0</alpha_stall>
      <cda_stall>1.4326647564469914</cda_stall>
      <cp>0 0 0</cp>
      <area>0.0004</area>
      <air_density>1.2041</air_density>
      <forward>0 1 0</forward>
      <upward>0 0 1</upward>
      <link_name>link_05</link_name>
    </plugin>
    <plugin name="link06_drag" filename="libLiftDragPlugin.so">
      <robotNamespace></robotNamespace>
      <a0>0</a0>
      <cla>0</cla>
      <cda>1.2535816618911175</cda>
      <alpha_stall>0</alpha_stall>
      <cda_stall>1.4326647564469914</cda_stall>
      <cp>0 0 0</cp>
      <area>0.0004</area>
      <air_density>1.2041</air_density>
      <forward>0 1 0</forward>
      <upward>0 0 1</upward>
      <link_name>link_06</link_name>
    </plugin>
    <plugin name="link07_drag" filename="libLiftDragPlugin.so">
      <robotNamespace></robotNamespace>
      <a0>0</a0>
      <cla>0</cla>
      <cda>1.2535816618911175</cda>
      <alpha_stall>0</alpha_stall>
      <cda_stall>1.4326647564469914</cda_stall>
      <cp>0 0 0</cp>
      <area>0.0004</area>
      <air_density>1.2041</air_density>
      <forward>0 1 0</forward>
      <upward>0 0 1</upward>
      <link_name>link_07</link_name>
    </plugin>
    <plugin name="link08_drag" filename="libLiftDragPlugin.so">
      <robotNamespace></robotNamespace>
      <a0>0</a0>
      <cla>0</cla>
      <cda>1.2535816618911175</cda>
      <alpha_stall>0</alpha_stall>
      <cda_stall>1.4326647564469914</cda_stall>
      <cp>0 0 0</cp>
      <area>0.0004</area>
      <air_density>1.2041</air_density>
      <forward>0 1 0</forward>
      <upward>0 0 1</upward>
      <link_name>link_08</link_name>
    </plugin>
    <plugin name="link09_drag" filename="libLiftDragPlugin.so">
      <robotNamespace></robotNamespace>
      <a0>0</a0>
      <cla>0</cla>
      <cda>1.2535816618911175</cda>
      <alpha_stall>0</alpha_stall>
      <cda_stall>1.4326647564469914</cda_stall>
      <cp>0 0 0</cp>
      <area>0.0004</area>
      <air_density>1.2041</air_density>
      <forward>0 1 0</forward>
      <upward>0 0 1</upward>
      <link_name>link_09</link_name>
    </plugin>
    <plugin name="link10_drag" filename="libLiftDragPlugin.so">
      <robotNamespace></robotNamespace>
      <a0>0</a0>
      <cla>0</cla>
      <cda>1.2535816618911175</cda>
      <alpha_stall>0</alpha_stall>
      <cda_stall>1.4326647564469914</cda_stall>
      <cp>0 0 0</cp>
      <area>0.0004</area>
      <air_density>1.2041</air_density>
      <forward>0 1 0</forward>
      <upward>0 0 1</upward>
      <link_name>link_10</link_name>
    </plugin>
    <plugin name="link11_drag" filename="libLiftDragPlugin.so">
      <robotNamespace></robotNamespace>
      <a0>0</a0>
      <cla>0</cla>
      <cda>1.2535816618911175</cda>
      <alpha_stall>0</alpha_stall>
      <cda_stall>1.4326647564469914</cda_stall>
      <cp>0 0 0</cp>
      <area>0.0004</area>
      <air_density>1.2041</air_density>
      <forward>0 1 0</forward>
      <upward>0 0 1</upward>
      <link_name>link_11</link_name>
    </plugin>
    <plugin name="link12_drag" filename="libLiftDragPlugin.so">
      <robotNamespace></robotNamespace>
      <a0>0</a0>
      <cla>0</cla>
      <cda>1.2535816618911175</cda>
      <alpha_stall>0</alpha_stall>
      <cda_stall>1.4326647564469914</cda_stall>
      <cp>0 0 0</cp>
      <area>0.0004</area>
      <air_density>1.2041</air_density>
      <forward>0 1 0</forward>
      <upward>0 0 1</upward>
      <link_name>link_12</link_name>
    </plugin>
    <plugin name="link13_drag" filename="libLiftDragPlugin.so">
      <robotNamespace></robotNamespace>
      <a0>0</a0>
      <cla>0</cla>
      <cda>1.2535816618911175</cda>
      <alpha_stall>0</alpha_stall>
      <cda_stall>1.4326647564469914</cda_stall>
      <cp>0 0 0</cp>
      <area>0.0004</area>
      <air_density>1.2041</air_density>
      <forward>0 1 0</forward>
      <upward>0 0 1</upward>
      <link_name>link_13</link_name>
    </plugin>
    <plugin name="link14_drag" filename="libLiftDragPlugin.so">
      <robotNamespace></robotNamespace>
      <a0>0</a0>
      <cla>0</cla>
      <cda>1.2535816618911175</cda>
      <alpha_stall>0</alpha_stall>
      <cda_stall>1.4326647564469914</cda_stall>
      <cp>0 0 0</cp>
      <area>0.0004</area>
      <air_density>1.2041</air_density>
      <forward>0 1 0</forward>
      <upward>0 0 1</upward>
      <link_name>link_14</link_name>
    </plugin>
    <plugin name="link15_drag" filename="libLiftDragPlugin.so">
      <robotNamespace></robotNamespace>
      <a0>0</a0>
      <cla>0</cla>
      <cda>1.2535816618911175</cda>
      <alpha_stall>0</alpha_stall>
      <cda_stall>1.4326647564469914</cda_stall>
      <cp>0 0 0</cp>
      <area>0.0004</area>
      <air_density>1.2041</air_density>
      <forward>0 1 0</forward>
      <upward>0 0 1</upward>
      <link_name>link_15</link_name>
    </plugin>
    <plugin name="link16_drag" filename="libLiftDragPlugin.so">
      <robotNamespace></robotNamespace>
      <a0>0</a0>
      <cla>0</cla>
      <cda>1.2535816618911175</cda>
      <alpha_stall>0</alpha_stall>
      <cda_stall>1.4326647564469914</cda_stall>
      <cp>0 0 0</cp>
      <area>0.0004</area>
      <air_density>1.2041</air_density>
      <forward>0 1 0</forward>
      <upward>0 0 1</upward>
      <link_name>link_16</link_name>
    </plugin>
    <plugin name="link17_drag" filename="libLiftDragPlugin.so">
      <robotNamespace></robotNamespace>
      <a0>0</a0>
      <cla>0</cla>
      <cda>1.2535816618911175</cda>
      <alpha_stall>0</alpha_stall>
      <cda_stall>1.4326647564469914</cda_stall>
      <cp>0 0 0</cp>
      <area>0.0004</area>
      <air_density>1.2041</air_density>
      <forward>0 1 0</forward>
      <upward>0 0 1</upward>
      <link_name>link_17</link_name>
    </plugin>
    <plugin name="link18_drag" filename="libLiftDragPlugin.so">
      <robotNamespace></robotNamespace>
      <a0>0</a0>
      <cla>0</cla>
      <cda>1.2535816618911175</cda>
      <alpha_stall>0</alpha_stall>
      <cda_stall>1.4326647564469914</cda_stall>
      <cp>0 0 0</cp>
      <area>0.0004</area>
      <air_density>1.2041</air_density>
      <forward>0 1 0</forward>
      <upward>0 0 1</upward>
      <link_name>link_18</link_name>
    </plugin>
    <plugin name="link19_drag" filename="libLiftDragPlugin.so">
      <robotNamespace></robotNamespace>
      <a0>0</a0>
      <cla>0</cla>
      <cda>1.2535816618911175</cda>
      <alpha_stall>0</alpha_stall>
      <cda_stall>1.4326647564469914</cda_stall>
      <cp>0 0 0</cp>
      <area>0.0004</area>
      <air_density>1.2041</air_density>
      <forward>0 1 0</forward>
      <upward>0 0 1</upward>
      <link_name>link_19</link_name>
    </plugin> -->
  </model>
</sdf>